{
 "cells": [
  {
   "cell_type": "code",
   "execution_count": 1,
   "id": "64ebe24c",
   "metadata": {},
   "outputs": [],
   "source": [
    "# Import SQLAlchemy dependencies\n",
    "import sqlalchemy\n",
    "from sqlalchemy.ext.automap import automap_base\n",
    "from sqlalchemy.orm import Session\n",
    "from sqlalchemy import create_engine, inspect\n",
    "import psycopg2"
   ]
  },
  {
   "cell_type": "code",
   "execution_count": 2,
   "id": "66f5aa1a",
   "metadata": {},
   "outputs": [],
   "source": [
    "# Create the connection engine\n",
    "engine = create_engine(\"postgresql://admin:postgres@localhost:5432/airport_db\")"
   ]
  },
  {
   "cell_type": "code",
   "execution_count": 3,
   "id": "02b1ea19",
   "metadata": {},
   "outputs": [
    {
     "ename": "OperationalError",
     "evalue": "(psycopg2.OperationalError) connection to server at \"localhost\" (::1), port 5432 failed: FATAL:  password authentication failed for user \"username\"\n\n(Background on this error at: https://sqlalche.me/e/14/e3q8)",
     "output_type": "error",
     "traceback": [
      "\u001b[1;31m---------------------------------------------------------------------------\u001b[0m",
      "\u001b[1;31mOperationalError\u001b[0m                          Traceback (most recent call last)",
      "File \u001b[1;32m~\\anaconda3\\envs\\dev\\Lib\\site-packages\\sqlalchemy\\engine\\base.py:3280\u001b[0m, in \u001b[0;36mEngine._wrap_pool_connect\u001b[1;34m(self, fn, connection)\u001b[0m\n\u001b[0;32m   3279\u001b[0m \u001b[38;5;28;01mtry\u001b[39;00m:\n\u001b[1;32m-> 3280\u001b[0m     \u001b[38;5;28;01mreturn\u001b[39;00m fn()\n\u001b[0;32m   3281\u001b[0m \u001b[38;5;28;01mexcept\u001b[39;00m dialect\u001b[38;5;241m.\u001b[39mdbapi\u001b[38;5;241m.\u001b[39mError \u001b[38;5;28;01mas\u001b[39;00m e:\n",
      "File \u001b[1;32m~\\anaconda3\\envs\\dev\\Lib\\site-packages\\sqlalchemy\\pool\\base.py:310\u001b[0m, in \u001b[0;36mPool.connect\u001b[1;34m(self)\u001b[0m\n\u001b[0;32m    303\u001b[0m \u001b[38;5;250m\u001b[39m\u001b[38;5;124;03m\"\"\"Return a DBAPI connection from the pool.\u001b[39;00m\n\u001b[0;32m    304\u001b[0m \n\u001b[0;32m    305\u001b[0m \u001b[38;5;124;03mThe connection is instrumented such that when its\u001b[39;00m\n\u001b[1;32m   (...)\u001b[0m\n\u001b[0;32m    308\u001b[0m \n\u001b[0;32m    309\u001b[0m \u001b[38;5;124;03m\"\"\"\u001b[39;00m\n\u001b[1;32m--> 310\u001b[0m \u001b[38;5;28;01mreturn\u001b[39;00m _ConnectionFairy\u001b[38;5;241m.\u001b[39m_checkout(\u001b[38;5;28mself\u001b[39m)\n",
      "File \u001b[1;32m~\\anaconda3\\envs\\dev\\Lib\\site-packages\\sqlalchemy\\pool\\base.py:868\u001b[0m, in \u001b[0;36m_ConnectionFairy._checkout\u001b[1;34m(cls, pool, threadconns, fairy)\u001b[0m\n\u001b[0;32m    867\u001b[0m \u001b[38;5;28;01mif\u001b[39;00m \u001b[38;5;129;01mnot\u001b[39;00m fairy:\n\u001b[1;32m--> 868\u001b[0m     fairy \u001b[38;5;241m=\u001b[39m _ConnectionRecord\u001b[38;5;241m.\u001b[39mcheckout(pool)\n\u001b[0;32m    870\u001b[0m     fairy\u001b[38;5;241m.\u001b[39m_pool \u001b[38;5;241m=\u001b[39m pool\n",
      "File \u001b[1;32m~\\anaconda3\\envs\\dev\\Lib\\site-packages\\sqlalchemy\\pool\\base.py:476\u001b[0m, in \u001b[0;36m_ConnectionRecord.checkout\u001b[1;34m(cls, pool)\u001b[0m\n\u001b[0;32m    474\u001b[0m \u001b[38;5;129m@classmethod\u001b[39m\n\u001b[0;32m    475\u001b[0m \u001b[38;5;28;01mdef\u001b[39;00m \u001b[38;5;21mcheckout\u001b[39m(\u001b[38;5;28mcls\u001b[39m, pool):\n\u001b[1;32m--> 476\u001b[0m     rec \u001b[38;5;241m=\u001b[39m pool\u001b[38;5;241m.\u001b[39m_do_get()\n\u001b[0;32m    477\u001b[0m     \u001b[38;5;28;01mtry\u001b[39;00m:\n",
      "File \u001b[1;32m~\\anaconda3\\envs\\dev\\Lib\\site-packages\\sqlalchemy\\pool\\impl.py:145\u001b[0m, in \u001b[0;36mQueuePool._do_get\u001b[1;34m(self)\u001b[0m\n\u001b[0;32m    144\u001b[0m \u001b[38;5;28;01mexcept\u001b[39;00m:\n\u001b[1;32m--> 145\u001b[0m     \u001b[38;5;28;01mwith\u001b[39;00m util\u001b[38;5;241m.\u001b[39msafe_reraise():\n\u001b[0;32m    146\u001b[0m         \u001b[38;5;28mself\u001b[39m\u001b[38;5;241m.\u001b[39m_dec_overflow()\n",
      "File \u001b[1;32m~\\anaconda3\\envs\\dev\\Lib\\site-packages\\sqlalchemy\\util\\langhelpers.py:70\u001b[0m, in \u001b[0;36msafe_reraise.__exit__\u001b[1;34m(self, type_, value, traceback)\u001b[0m\n\u001b[0;32m     69\u001b[0m     \u001b[38;5;28;01mif\u001b[39;00m \u001b[38;5;129;01mnot\u001b[39;00m \u001b[38;5;28mself\u001b[39m\u001b[38;5;241m.\u001b[39mwarn_only:\n\u001b[1;32m---> 70\u001b[0m         compat\u001b[38;5;241m.\u001b[39mraise_(\n\u001b[0;32m     71\u001b[0m             exc_value,\n\u001b[0;32m     72\u001b[0m             with_traceback\u001b[38;5;241m=\u001b[39mexc_tb,\n\u001b[0;32m     73\u001b[0m         )\n\u001b[0;32m     74\u001b[0m \u001b[38;5;28;01melse\u001b[39;00m:\n",
      "File \u001b[1;32m~\\anaconda3\\envs\\dev\\Lib\\site-packages\\sqlalchemy\\util\\compat.py:208\u001b[0m, in \u001b[0;36mraise_\u001b[1;34m(***failed resolving arguments***)\u001b[0m\n\u001b[0;32m    207\u001b[0m \u001b[38;5;28;01mtry\u001b[39;00m:\n\u001b[1;32m--> 208\u001b[0m     \u001b[38;5;28;01mraise\u001b[39;00m exception\n\u001b[0;32m    209\u001b[0m \u001b[38;5;28;01mfinally\u001b[39;00m:\n\u001b[0;32m    210\u001b[0m     \u001b[38;5;66;03m# credit to\u001b[39;00m\n\u001b[0;32m    211\u001b[0m     \u001b[38;5;66;03m# https://cosmicpercolator.com/2016/01/13/exception-leaks-in-python-2-and-3/\u001b[39;00m\n\u001b[0;32m    212\u001b[0m     \u001b[38;5;66;03m# as the __traceback__ object creates a cycle\u001b[39;00m\n",
      "File \u001b[1;32m~\\anaconda3\\envs\\dev\\Lib\\site-packages\\sqlalchemy\\pool\\impl.py:143\u001b[0m, in \u001b[0;36mQueuePool._do_get\u001b[1;34m(self)\u001b[0m\n\u001b[0;32m    142\u001b[0m \u001b[38;5;28;01mtry\u001b[39;00m:\n\u001b[1;32m--> 143\u001b[0m     \u001b[38;5;28;01mreturn\u001b[39;00m \u001b[38;5;28mself\u001b[39m\u001b[38;5;241m.\u001b[39m_create_connection()\n\u001b[0;32m    144\u001b[0m \u001b[38;5;28;01mexcept\u001b[39;00m:\n",
      "File \u001b[1;32m~\\anaconda3\\envs\\dev\\Lib\\site-packages\\sqlalchemy\\pool\\base.py:256\u001b[0m, in \u001b[0;36mPool._create_connection\u001b[1;34m(self)\u001b[0m\n\u001b[0;32m    254\u001b[0m \u001b[38;5;250m\u001b[39m\u001b[38;5;124;03m\"\"\"Called by subclasses to create a new ConnectionRecord.\"\"\"\u001b[39;00m\n\u001b[1;32m--> 256\u001b[0m \u001b[38;5;28;01mreturn\u001b[39;00m _ConnectionRecord(\u001b[38;5;28mself\u001b[39m)\n",
      "File \u001b[1;32m~\\anaconda3\\envs\\dev\\Lib\\site-packages\\sqlalchemy\\pool\\base.py:371\u001b[0m, in \u001b[0;36m_ConnectionRecord.__init__\u001b[1;34m(self, pool, connect)\u001b[0m\n\u001b[0;32m    370\u001b[0m \u001b[38;5;28;01mif\u001b[39;00m connect:\n\u001b[1;32m--> 371\u001b[0m     \u001b[38;5;28mself\u001b[39m\u001b[38;5;241m.\u001b[39m__connect()\n\u001b[0;32m    372\u001b[0m \u001b[38;5;28mself\u001b[39m\u001b[38;5;241m.\u001b[39mfinalize_callback \u001b[38;5;241m=\u001b[39m deque()\n",
      "File \u001b[1;32m~\\anaconda3\\envs\\dev\\Lib\\site-packages\\sqlalchemy\\pool\\base.py:665\u001b[0m, in \u001b[0;36m_ConnectionRecord.__connect\u001b[1;34m(self)\u001b[0m\n\u001b[0;32m    664\u001b[0m \u001b[38;5;28;01mexcept\u001b[39;00m \u001b[38;5;167;01mException\u001b[39;00m \u001b[38;5;28;01mas\u001b[39;00m e:\n\u001b[1;32m--> 665\u001b[0m     \u001b[38;5;28;01mwith\u001b[39;00m util\u001b[38;5;241m.\u001b[39msafe_reraise():\n\u001b[0;32m    666\u001b[0m         pool\u001b[38;5;241m.\u001b[39mlogger\u001b[38;5;241m.\u001b[39mdebug(\u001b[38;5;124m\"\u001b[39m\u001b[38;5;124mError on connect(): \u001b[39m\u001b[38;5;132;01m%s\u001b[39;00m\u001b[38;5;124m\"\u001b[39m, e)\n",
      "File \u001b[1;32m~\\anaconda3\\envs\\dev\\Lib\\site-packages\\sqlalchemy\\util\\langhelpers.py:70\u001b[0m, in \u001b[0;36msafe_reraise.__exit__\u001b[1;34m(self, type_, value, traceback)\u001b[0m\n\u001b[0;32m     69\u001b[0m     \u001b[38;5;28;01mif\u001b[39;00m \u001b[38;5;129;01mnot\u001b[39;00m \u001b[38;5;28mself\u001b[39m\u001b[38;5;241m.\u001b[39mwarn_only:\n\u001b[1;32m---> 70\u001b[0m         compat\u001b[38;5;241m.\u001b[39mraise_(\n\u001b[0;32m     71\u001b[0m             exc_value,\n\u001b[0;32m     72\u001b[0m             with_traceback\u001b[38;5;241m=\u001b[39mexc_tb,\n\u001b[0;32m     73\u001b[0m         )\n\u001b[0;32m     74\u001b[0m \u001b[38;5;28;01melse\u001b[39;00m:\n",
      "File \u001b[1;32m~\\anaconda3\\envs\\dev\\Lib\\site-packages\\sqlalchemy\\util\\compat.py:208\u001b[0m, in \u001b[0;36mraise_\u001b[1;34m(***failed resolving arguments***)\u001b[0m\n\u001b[0;32m    207\u001b[0m \u001b[38;5;28;01mtry\u001b[39;00m:\n\u001b[1;32m--> 208\u001b[0m     \u001b[38;5;28;01mraise\u001b[39;00m exception\n\u001b[0;32m    209\u001b[0m \u001b[38;5;28;01mfinally\u001b[39;00m:\n\u001b[0;32m    210\u001b[0m     \u001b[38;5;66;03m# credit to\u001b[39;00m\n\u001b[0;32m    211\u001b[0m     \u001b[38;5;66;03m# https://cosmicpercolator.com/2016/01/13/exception-leaks-in-python-2-and-3/\u001b[39;00m\n\u001b[0;32m    212\u001b[0m     \u001b[38;5;66;03m# as the __traceback__ object creates a cycle\u001b[39;00m\n",
      "File \u001b[1;32m~\\anaconda3\\envs\\dev\\Lib\\site-packages\\sqlalchemy\\pool\\base.py:661\u001b[0m, in \u001b[0;36m_ConnectionRecord.__connect\u001b[1;34m(self)\u001b[0m\n\u001b[0;32m    660\u001b[0m \u001b[38;5;28mself\u001b[39m\u001b[38;5;241m.\u001b[39mstarttime \u001b[38;5;241m=\u001b[39m time\u001b[38;5;241m.\u001b[39mtime()\n\u001b[1;32m--> 661\u001b[0m \u001b[38;5;28mself\u001b[39m\u001b[38;5;241m.\u001b[39mdbapi_connection \u001b[38;5;241m=\u001b[39m connection \u001b[38;5;241m=\u001b[39m pool\u001b[38;5;241m.\u001b[39m_invoke_creator(\u001b[38;5;28mself\u001b[39m)\n\u001b[0;32m    662\u001b[0m pool\u001b[38;5;241m.\u001b[39mlogger\u001b[38;5;241m.\u001b[39mdebug(\u001b[38;5;124m\"\u001b[39m\u001b[38;5;124mCreated new connection \u001b[39m\u001b[38;5;132;01m%r\u001b[39;00m\u001b[38;5;124m\"\u001b[39m, connection)\n",
      "File \u001b[1;32m~\\anaconda3\\envs\\dev\\Lib\\site-packages\\sqlalchemy\\engine\\create.py:590\u001b[0m, in \u001b[0;36mcreate_engine.<locals>.connect\u001b[1;34m(connection_record)\u001b[0m\n\u001b[0;32m    589\u001b[0m             \u001b[38;5;28;01mreturn\u001b[39;00m connection\n\u001b[1;32m--> 590\u001b[0m \u001b[38;5;28;01mreturn\u001b[39;00m dialect\u001b[38;5;241m.\u001b[39mconnect(\u001b[38;5;241m*\u001b[39mcargs, \u001b[38;5;241m*\u001b[39m\u001b[38;5;241m*\u001b[39mcparams)\n",
      "File \u001b[1;32m~\\anaconda3\\envs\\dev\\Lib\\site-packages\\sqlalchemy\\engine\\default.py:597\u001b[0m, in \u001b[0;36mDefaultDialect.connect\u001b[1;34m(self, *cargs, **cparams)\u001b[0m\n\u001b[0;32m    595\u001b[0m \u001b[38;5;28;01mdef\u001b[39;00m \u001b[38;5;21mconnect\u001b[39m(\u001b[38;5;28mself\u001b[39m, \u001b[38;5;241m*\u001b[39mcargs, \u001b[38;5;241m*\u001b[39m\u001b[38;5;241m*\u001b[39mcparams):\n\u001b[0;32m    596\u001b[0m     \u001b[38;5;66;03m# inherits the docstring from interfaces.Dialect.connect\u001b[39;00m\n\u001b[1;32m--> 597\u001b[0m     \u001b[38;5;28;01mreturn\u001b[39;00m \u001b[38;5;28mself\u001b[39m\u001b[38;5;241m.\u001b[39mdbapi\u001b[38;5;241m.\u001b[39mconnect(\u001b[38;5;241m*\u001b[39mcargs, \u001b[38;5;241m*\u001b[39m\u001b[38;5;241m*\u001b[39mcparams)\n",
      "File \u001b[1;32m~\\anaconda3\\envs\\dev\\Lib\\site-packages\\psycopg2\\__init__.py:122\u001b[0m, in \u001b[0;36mconnect\u001b[1;34m(dsn, connection_factory, cursor_factory, **kwargs)\u001b[0m\n\u001b[0;32m    121\u001b[0m dsn \u001b[38;5;241m=\u001b[39m _ext\u001b[38;5;241m.\u001b[39mmake_dsn(dsn, \u001b[38;5;241m*\u001b[39m\u001b[38;5;241m*\u001b[39mkwargs)\n\u001b[1;32m--> 122\u001b[0m conn \u001b[38;5;241m=\u001b[39m _connect(dsn, connection_factory\u001b[38;5;241m=\u001b[39mconnection_factory, \u001b[38;5;241m*\u001b[39m\u001b[38;5;241m*\u001b[39mkwasync)\n\u001b[0;32m    123\u001b[0m \u001b[38;5;28;01mif\u001b[39;00m cursor_factory \u001b[38;5;129;01mis\u001b[39;00m \u001b[38;5;129;01mnot\u001b[39;00m \u001b[38;5;28;01mNone\u001b[39;00m:\n",
      "\u001b[1;31mOperationalError\u001b[0m: connection to server at \"localhost\" (::1), port 5432 failed: FATAL:  password authentication failed for user \"username\"\n",
      "\nThe above exception was the direct cause of the following exception:\n",
      "\u001b[1;31mOperationalError\u001b[0m                          Traceback (most recent call last)",
      "Cell \u001b[1;32mIn[3], line 2\u001b[0m\n\u001b[0;32m      1\u001b[0m \u001b[38;5;66;03m# Create the inspector and connect it to the engine\u001b[39;00m\n\u001b[1;32m----> 2\u001b[0m inspector \u001b[38;5;241m=\u001b[39m inspect(engine)\n",
      "File \u001b[1;32m~\\anaconda3\\envs\\dev\\Lib\\site-packages\\sqlalchemy\\inspection.py:64\u001b[0m, in \u001b[0;36minspect\u001b[1;34m(subject, raiseerr)\u001b[0m\n\u001b[0;32m     62\u001b[0m \u001b[38;5;28;01mif\u001b[39;00m reg \u001b[38;5;129;01mis\u001b[39;00m \u001b[38;5;28;01mTrue\u001b[39;00m:\n\u001b[0;32m     63\u001b[0m     \u001b[38;5;28;01mreturn\u001b[39;00m subject\n\u001b[1;32m---> 64\u001b[0m ret \u001b[38;5;241m=\u001b[39m reg(subject)\n\u001b[0;32m     65\u001b[0m \u001b[38;5;28;01mif\u001b[39;00m ret \u001b[38;5;129;01mis\u001b[39;00m \u001b[38;5;129;01mnot\u001b[39;00m \u001b[38;5;28;01mNone\u001b[39;00m:\n\u001b[0;32m     66\u001b[0m     \u001b[38;5;28;01mbreak\u001b[39;00m\n",
      "File \u001b[1;32m~\\anaconda3\\envs\\dev\\Lib\\site-packages\\sqlalchemy\\engine\\reflection.py:182\u001b[0m, in \u001b[0;36mInspector._engine_insp\u001b[1;34m(bind)\u001b[0m\n\u001b[0;32m    180\u001b[0m \u001b[38;5;129m@inspection\u001b[39m\u001b[38;5;241m.\u001b[39m_inspects(Engine)\n\u001b[0;32m    181\u001b[0m \u001b[38;5;28;01mdef\u001b[39;00m \u001b[38;5;21m_engine_insp\u001b[39m(bind):\n\u001b[1;32m--> 182\u001b[0m     \u001b[38;5;28;01mreturn\u001b[39;00m Inspector\u001b[38;5;241m.\u001b[39m_construct(Inspector\u001b[38;5;241m.\u001b[39m_init_engine, bind)\n",
      "File \u001b[1;32m~\\anaconda3\\envs\\dev\\Lib\\site-packages\\sqlalchemy\\engine\\reflection.py:117\u001b[0m, in \u001b[0;36mInspector._construct\u001b[1;34m(cls, init, bind)\u001b[0m\n\u001b[0;32m    114\u001b[0m     \u001b[38;5;28mcls\u001b[39m \u001b[38;5;241m=\u001b[39m bind\u001b[38;5;241m.\u001b[39mdialect\u001b[38;5;241m.\u001b[39minspector\n\u001b[0;32m    116\u001b[0m \u001b[38;5;28mself\u001b[39m \u001b[38;5;241m=\u001b[39m \u001b[38;5;28mcls\u001b[39m\u001b[38;5;241m.\u001b[39m\u001b[38;5;21m__new__\u001b[39m(\u001b[38;5;28mcls\u001b[39m)\n\u001b[1;32m--> 117\u001b[0m init(\u001b[38;5;28mself\u001b[39m, bind)\n\u001b[0;32m    118\u001b[0m \u001b[38;5;28;01mreturn\u001b[39;00m \u001b[38;5;28mself\u001b[39m\n",
      "File \u001b[1;32m~\\anaconda3\\envs\\dev\\Lib\\site-packages\\sqlalchemy\\engine\\reflection.py:128\u001b[0m, in \u001b[0;36mInspector._init_engine\u001b[1;34m(self, engine)\u001b[0m\n\u001b[0;32m    126\u001b[0m \u001b[38;5;28;01mdef\u001b[39;00m \u001b[38;5;21m_init_engine\u001b[39m(\u001b[38;5;28mself\u001b[39m, engine):\n\u001b[0;32m    127\u001b[0m     \u001b[38;5;28mself\u001b[39m\u001b[38;5;241m.\u001b[39mbind \u001b[38;5;241m=\u001b[39m \u001b[38;5;28mself\u001b[39m\u001b[38;5;241m.\u001b[39mengine \u001b[38;5;241m=\u001b[39m engine\n\u001b[1;32m--> 128\u001b[0m     engine\u001b[38;5;241m.\u001b[39mconnect()\u001b[38;5;241m.\u001b[39mclose()\n\u001b[0;32m    129\u001b[0m     \u001b[38;5;28mself\u001b[39m\u001b[38;5;241m.\u001b[39m_op_context_requires_connect \u001b[38;5;241m=\u001b[39m \u001b[38;5;28;01mTrue\u001b[39;00m\n\u001b[0;32m    130\u001b[0m     \u001b[38;5;28mself\u001b[39m\u001b[38;5;241m.\u001b[39mdialect \u001b[38;5;241m=\u001b[39m \u001b[38;5;28mself\u001b[39m\u001b[38;5;241m.\u001b[39mengine\u001b[38;5;241m.\u001b[39mdialect\n",
      "File \u001b[1;32m~\\anaconda3\\envs\\dev\\Lib\\site-packages\\sqlalchemy\\engine\\base.py:3234\u001b[0m, in \u001b[0;36mEngine.connect\u001b[1;34m(self, close_with_result)\u001b[0m\n\u001b[0;32m   3219\u001b[0m \u001b[38;5;28;01mdef\u001b[39;00m \u001b[38;5;21mconnect\u001b[39m(\u001b[38;5;28mself\u001b[39m, close_with_result\u001b[38;5;241m=\u001b[39m\u001b[38;5;28;01mFalse\u001b[39;00m):\n\u001b[0;32m   3220\u001b[0m \u001b[38;5;250m    \u001b[39m\u001b[38;5;124;03m\"\"\"Return a new :class:`_engine.Connection` object.\u001b[39;00m\n\u001b[0;32m   3221\u001b[0m \n\u001b[0;32m   3222\u001b[0m \u001b[38;5;124;03m    The :class:`_engine.Connection` object is a facade that uses a DBAPI\u001b[39;00m\n\u001b[1;32m   (...)\u001b[0m\n\u001b[0;32m   3231\u001b[0m \n\u001b[0;32m   3232\u001b[0m \u001b[38;5;124;03m    \"\"\"\u001b[39;00m\n\u001b[1;32m-> 3234\u001b[0m     \u001b[38;5;28;01mreturn\u001b[39;00m \u001b[38;5;28mself\u001b[39m\u001b[38;5;241m.\u001b[39m_connection_cls(\u001b[38;5;28mself\u001b[39m, close_with_result\u001b[38;5;241m=\u001b[39mclose_with_result)\n",
      "File \u001b[1;32m~\\anaconda3\\envs\\dev\\Lib\\site-packages\\sqlalchemy\\engine\\base.py:96\u001b[0m, in \u001b[0;36mConnection.__init__\u001b[1;34m(self, engine, connection, close_with_result, _branch_from, _execution_options, _dispatch, _has_events, _allow_revalidate)\u001b[0m\n\u001b[0;32m     91\u001b[0m     \u001b[38;5;28mself\u001b[39m\u001b[38;5;241m.\u001b[39m_has_events \u001b[38;5;241m=\u001b[39m _branch_from\u001b[38;5;241m.\u001b[39m_has_events\n\u001b[0;32m     92\u001b[0m \u001b[38;5;28;01melse\u001b[39;00m:\n\u001b[0;32m     93\u001b[0m     \u001b[38;5;28mself\u001b[39m\u001b[38;5;241m.\u001b[39m_dbapi_connection \u001b[38;5;241m=\u001b[39m (\n\u001b[0;32m     94\u001b[0m         connection\n\u001b[0;32m     95\u001b[0m         \u001b[38;5;28;01mif\u001b[39;00m connection \u001b[38;5;129;01mis\u001b[39;00m \u001b[38;5;129;01mnot\u001b[39;00m \u001b[38;5;28;01mNone\u001b[39;00m\n\u001b[1;32m---> 96\u001b[0m         \u001b[38;5;28;01melse\u001b[39;00m engine\u001b[38;5;241m.\u001b[39mraw_connection()\n\u001b[0;32m     97\u001b[0m     )\n\u001b[0;32m     99\u001b[0m     \u001b[38;5;28mself\u001b[39m\u001b[38;5;241m.\u001b[39m_transaction \u001b[38;5;241m=\u001b[39m \u001b[38;5;28mself\u001b[39m\u001b[38;5;241m.\u001b[39m_nested_transaction \u001b[38;5;241m=\u001b[39m \u001b[38;5;28;01mNone\u001b[39;00m\n\u001b[0;32m    100\u001b[0m     \u001b[38;5;28mself\u001b[39m\u001b[38;5;241m.\u001b[39m__savepoint_seq \u001b[38;5;241m=\u001b[39m \u001b[38;5;241m0\u001b[39m\n",
      "File \u001b[1;32m~\\anaconda3\\envs\\dev\\Lib\\site-packages\\sqlalchemy\\engine\\base.py:3313\u001b[0m, in \u001b[0;36mEngine.raw_connection\u001b[1;34m(self, _connection)\u001b[0m\n\u001b[0;32m   3291\u001b[0m \u001b[38;5;28;01mdef\u001b[39;00m \u001b[38;5;21mraw_connection\u001b[39m(\u001b[38;5;28mself\u001b[39m, _connection\u001b[38;5;241m=\u001b[39m\u001b[38;5;28;01mNone\u001b[39;00m):\n\u001b[0;32m   3292\u001b[0m \u001b[38;5;250m    \u001b[39m\u001b[38;5;124;03m\"\"\"Return a \"raw\" DBAPI connection from the connection pool.\u001b[39;00m\n\u001b[0;32m   3293\u001b[0m \n\u001b[0;32m   3294\u001b[0m \u001b[38;5;124;03m    The returned object is a proxied version of the DBAPI\u001b[39;00m\n\u001b[1;32m   (...)\u001b[0m\n\u001b[0;32m   3311\u001b[0m \n\u001b[0;32m   3312\u001b[0m \u001b[38;5;124;03m    \"\"\"\u001b[39;00m\n\u001b[1;32m-> 3313\u001b[0m     \u001b[38;5;28;01mreturn\u001b[39;00m \u001b[38;5;28mself\u001b[39m\u001b[38;5;241m.\u001b[39m_wrap_pool_connect(\u001b[38;5;28mself\u001b[39m\u001b[38;5;241m.\u001b[39mpool\u001b[38;5;241m.\u001b[39mconnect, _connection)\n",
      "File \u001b[1;32m~\\anaconda3\\envs\\dev\\Lib\\site-packages\\sqlalchemy\\engine\\base.py:3283\u001b[0m, in \u001b[0;36mEngine._wrap_pool_connect\u001b[1;34m(self, fn, connection)\u001b[0m\n\u001b[0;32m   3281\u001b[0m \u001b[38;5;28;01mexcept\u001b[39;00m dialect\u001b[38;5;241m.\u001b[39mdbapi\u001b[38;5;241m.\u001b[39mError \u001b[38;5;28;01mas\u001b[39;00m e:\n\u001b[0;32m   3282\u001b[0m     \u001b[38;5;28;01mif\u001b[39;00m connection \u001b[38;5;129;01mis\u001b[39;00m \u001b[38;5;28;01mNone\u001b[39;00m:\n\u001b[1;32m-> 3283\u001b[0m         Connection\u001b[38;5;241m.\u001b[39m_handle_dbapi_exception_noconnection(\n\u001b[0;32m   3284\u001b[0m             e, dialect, \u001b[38;5;28mself\u001b[39m\n\u001b[0;32m   3285\u001b[0m         )\n\u001b[0;32m   3286\u001b[0m     \u001b[38;5;28;01melse\u001b[39;00m:\n\u001b[0;32m   3287\u001b[0m         util\u001b[38;5;241m.\u001b[39mraise_(\n\u001b[0;32m   3288\u001b[0m             sys\u001b[38;5;241m.\u001b[39mexc_info()[\u001b[38;5;241m1\u001b[39m], with_traceback\u001b[38;5;241m=\u001b[39msys\u001b[38;5;241m.\u001b[39mexc_info()[\u001b[38;5;241m2\u001b[39m]\n\u001b[0;32m   3289\u001b[0m         )\n",
      "File \u001b[1;32m~\\anaconda3\\envs\\dev\\Lib\\site-packages\\sqlalchemy\\engine\\base.py:2117\u001b[0m, in \u001b[0;36mConnection._handle_dbapi_exception_noconnection\u001b[1;34m(cls, e, dialect, engine)\u001b[0m\n\u001b[0;32m   2115\u001b[0m     util\u001b[38;5;241m.\u001b[39mraise_(newraise, with_traceback\u001b[38;5;241m=\u001b[39mexc_info[\u001b[38;5;241m2\u001b[39m], from_\u001b[38;5;241m=\u001b[39me)\n\u001b[0;32m   2116\u001b[0m \u001b[38;5;28;01melif\u001b[39;00m should_wrap:\n\u001b[1;32m-> 2117\u001b[0m     util\u001b[38;5;241m.\u001b[39mraise_(\n\u001b[0;32m   2118\u001b[0m         sqlalchemy_exception, with_traceback\u001b[38;5;241m=\u001b[39mexc_info[\u001b[38;5;241m2\u001b[39m], from_\u001b[38;5;241m=\u001b[39me\n\u001b[0;32m   2119\u001b[0m     )\n\u001b[0;32m   2120\u001b[0m \u001b[38;5;28;01melse\u001b[39;00m:\n\u001b[0;32m   2121\u001b[0m     util\u001b[38;5;241m.\u001b[39mraise_(exc_info[\u001b[38;5;241m1\u001b[39m], with_traceback\u001b[38;5;241m=\u001b[39mexc_info[\u001b[38;5;241m2\u001b[39m])\n",
      "File \u001b[1;32m~\\anaconda3\\envs\\dev\\Lib\\site-packages\\sqlalchemy\\util\\compat.py:208\u001b[0m, in \u001b[0;36mraise_\u001b[1;34m(***failed resolving arguments***)\u001b[0m\n\u001b[0;32m    205\u001b[0m     exception\u001b[38;5;241m.\u001b[39m__cause__ \u001b[38;5;241m=\u001b[39m replace_context\n\u001b[0;32m    207\u001b[0m \u001b[38;5;28;01mtry\u001b[39;00m:\n\u001b[1;32m--> 208\u001b[0m     \u001b[38;5;28;01mraise\u001b[39;00m exception\n\u001b[0;32m    209\u001b[0m \u001b[38;5;28;01mfinally\u001b[39;00m:\n\u001b[0;32m    210\u001b[0m     \u001b[38;5;66;03m# credit to\u001b[39;00m\n\u001b[0;32m    211\u001b[0m     \u001b[38;5;66;03m# https://cosmicpercolator.com/2016/01/13/exception-leaks-in-python-2-and-3/\u001b[39;00m\n\u001b[0;32m    212\u001b[0m     \u001b[38;5;66;03m# as the __traceback__ object creates a cycle\u001b[39;00m\n\u001b[0;32m    213\u001b[0m     \u001b[38;5;28;01mdel\u001b[39;00m exception, replace_context, from_, with_traceback\n",
      "File \u001b[1;32m~\\anaconda3\\envs\\dev\\Lib\\site-packages\\sqlalchemy\\engine\\base.py:3280\u001b[0m, in \u001b[0;36mEngine._wrap_pool_connect\u001b[1;34m(self, fn, connection)\u001b[0m\n\u001b[0;32m   3278\u001b[0m dialect \u001b[38;5;241m=\u001b[39m \u001b[38;5;28mself\u001b[39m\u001b[38;5;241m.\u001b[39mdialect\n\u001b[0;32m   3279\u001b[0m \u001b[38;5;28;01mtry\u001b[39;00m:\n\u001b[1;32m-> 3280\u001b[0m     \u001b[38;5;28;01mreturn\u001b[39;00m fn()\n\u001b[0;32m   3281\u001b[0m \u001b[38;5;28;01mexcept\u001b[39;00m dialect\u001b[38;5;241m.\u001b[39mdbapi\u001b[38;5;241m.\u001b[39mError \u001b[38;5;28;01mas\u001b[39;00m e:\n\u001b[0;32m   3282\u001b[0m     \u001b[38;5;28;01mif\u001b[39;00m connection \u001b[38;5;129;01mis\u001b[39;00m \u001b[38;5;28;01mNone\u001b[39;00m:\n",
      "File \u001b[1;32m~\\anaconda3\\envs\\dev\\Lib\\site-packages\\sqlalchemy\\pool\\base.py:310\u001b[0m, in \u001b[0;36mPool.connect\u001b[1;34m(self)\u001b[0m\n\u001b[0;32m    302\u001b[0m \u001b[38;5;28;01mdef\u001b[39;00m \u001b[38;5;21mconnect\u001b[39m(\u001b[38;5;28mself\u001b[39m):\n\u001b[0;32m    303\u001b[0m \u001b[38;5;250m    \u001b[39m\u001b[38;5;124;03m\"\"\"Return a DBAPI connection from the pool.\u001b[39;00m\n\u001b[0;32m    304\u001b[0m \n\u001b[0;32m    305\u001b[0m \u001b[38;5;124;03m    The connection is instrumented such that when its\u001b[39;00m\n\u001b[1;32m   (...)\u001b[0m\n\u001b[0;32m    308\u001b[0m \n\u001b[0;32m    309\u001b[0m \u001b[38;5;124;03m    \"\"\"\u001b[39;00m\n\u001b[1;32m--> 310\u001b[0m     \u001b[38;5;28;01mreturn\u001b[39;00m _ConnectionFairy\u001b[38;5;241m.\u001b[39m_checkout(\u001b[38;5;28mself\u001b[39m)\n",
      "File \u001b[1;32m~\\anaconda3\\envs\\dev\\Lib\\site-packages\\sqlalchemy\\pool\\base.py:868\u001b[0m, in \u001b[0;36m_ConnectionFairy._checkout\u001b[1;34m(cls, pool, threadconns, fairy)\u001b[0m\n\u001b[0;32m    865\u001b[0m \u001b[38;5;129m@classmethod\u001b[39m\n\u001b[0;32m    866\u001b[0m \u001b[38;5;28;01mdef\u001b[39;00m \u001b[38;5;21m_checkout\u001b[39m(\u001b[38;5;28mcls\u001b[39m, pool, threadconns\u001b[38;5;241m=\u001b[39m\u001b[38;5;28;01mNone\u001b[39;00m, fairy\u001b[38;5;241m=\u001b[39m\u001b[38;5;28;01mNone\u001b[39;00m):\n\u001b[0;32m    867\u001b[0m     \u001b[38;5;28;01mif\u001b[39;00m \u001b[38;5;129;01mnot\u001b[39;00m fairy:\n\u001b[1;32m--> 868\u001b[0m         fairy \u001b[38;5;241m=\u001b[39m _ConnectionRecord\u001b[38;5;241m.\u001b[39mcheckout(pool)\n\u001b[0;32m    870\u001b[0m         fairy\u001b[38;5;241m.\u001b[39m_pool \u001b[38;5;241m=\u001b[39m pool\n\u001b[0;32m    871\u001b[0m         fairy\u001b[38;5;241m.\u001b[39m_counter \u001b[38;5;241m=\u001b[39m \u001b[38;5;241m0\u001b[39m\n",
      "File \u001b[1;32m~\\anaconda3\\envs\\dev\\Lib\\site-packages\\sqlalchemy\\pool\\base.py:476\u001b[0m, in \u001b[0;36m_ConnectionRecord.checkout\u001b[1;34m(cls, pool)\u001b[0m\n\u001b[0;32m    474\u001b[0m \u001b[38;5;129m@classmethod\u001b[39m\n\u001b[0;32m    475\u001b[0m \u001b[38;5;28;01mdef\u001b[39;00m \u001b[38;5;21mcheckout\u001b[39m(\u001b[38;5;28mcls\u001b[39m, pool):\n\u001b[1;32m--> 476\u001b[0m     rec \u001b[38;5;241m=\u001b[39m pool\u001b[38;5;241m.\u001b[39m_do_get()\n\u001b[0;32m    477\u001b[0m     \u001b[38;5;28;01mtry\u001b[39;00m:\n\u001b[0;32m    478\u001b[0m         dbapi_connection \u001b[38;5;241m=\u001b[39m rec\u001b[38;5;241m.\u001b[39mget_connection()\n",
      "File \u001b[1;32m~\\anaconda3\\envs\\dev\\Lib\\site-packages\\sqlalchemy\\pool\\impl.py:145\u001b[0m, in \u001b[0;36mQueuePool._do_get\u001b[1;34m(self)\u001b[0m\n\u001b[0;32m    143\u001b[0m         \u001b[38;5;28;01mreturn\u001b[39;00m \u001b[38;5;28mself\u001b[39m\u001b[38;5;241m.\u001b[39m_create_connection()\n\u001b[0;32m    144\u001b[0m     \u001b[38;5;28;01mexcept\u001b[39;00m:\n\u001b[1;32m--> 145\u001b[0m         \u001b[38;5;28;01mwith\u001b[39;00m util\u001b[38;5;241m.\u001b[39msafe_reraise():\n\u001b[0;32m    146\u001b[0m             \u001b[38;5;28mself\u001b[39m\u001b[38;5;241m.\u001b[39m_dec_overflow()\n\u001b[0;32m    147\u001b[0m \u001b[38;5;28;01melse\u001b[39;00m:\n",
      "File \u001b[1;32m~\\anaconda3\\envs\\dev\\Lib\\site-packages\\sqlalchemy\\util\\langhelpers.py:70\u001b[0m, in \u001b[0;36msafe_reraise.__exit__\u001b[1;34m(self, type_, value, traceback)\u001b[0m\n\u001b[0;32m     68\u001b[0m     \u001b[38;5;28mself\u001b[39m\u001b[38;5;241m.\u001b[39m_exc_info \u001b[38;5;241m=\u001b[39m \u001b[38;5;28;01mNone\u001b[39;00m  \u001b[38;5;66;03m# remove potential circular references\u001b[39;00m\n\u001b[0;32m     69\u001b[0m     \u001b[38;5;28;01mif\u001b[39;00m \u001b[38;5;129;01mnot\u001b[39;00m \u001b[38;5;28mself\u001b[39m\u001b[38;5;241m.\u001b[39mwarn_only:\n\u001b[1;32m---> 70\u001b[0m         compat\u001b[38;5;241m.\u001b[39mraise_(\n\u001b[0;32m     71\u001b[0m             exc_value,\n\u001b[0;32m     72\u001b[0m             with_traceback\u001b[38;5;241m=\u001b[39mexc_tb,\n\u001b[0;32m     73\u001b[0m         )\n\u001b[0;32m     74\u001b[0m \u001b[38;5;28;01melse\u001b[39;00m:\n\u001b[0;32m     75\u001b[0m     \u001b[38;5;28;01mif\u001b[39;00m \u001b[38;5;129;01mnot\u001b[39;00m compat\u001b[38;5;241m.\u001b[39mpy3k \u001b[38;5;129;01mand\u001b[39;00m \u001b[38;5;28mself\u001b[39m\u001b[38;5;241m.\u001b[39m_exc_info \u001b[38;5;129;01mand\u001b[39;00m \u001b[38;5;28mself\u001b[39m\u001b[38;5;241m.\u001b[39m_exc_info[\u001b[38;5;241m1\u001b[39m]:\n\u001b[0;32m     76\u001b[0m         \u001b[38;5;66;03m# emulate Py3K's behavior of telling us when an exception\u001b[39;00m\n\u001b[0;32m     77\u001b[0m         \u001b[38;5;66;03m# occurs in an exception handler.\u001b[39;00m\n",
      "File \u001b[1;32m~\\anaconda3\\envs\\dev\\Lib\\site-packages\\sqlalchemy\\util\\compat.py:208\u001b[0m, in \u001b[0;36mraise_\u001b[1;34m(***failed resolving arguments***)\u001b[0m\n\u001b[0;32m    205\u001b[0m     exception\u001b[38;5;241m.\u001b[39m__cause__ \u001b[38;5;241m=\u001b[39m replace_context\n\u001b[0;32m    207\u001b[0m \u001b[38;5;28;01mtry\u001b[39;00m:\n\u001b[1;32m--> 208\u001b[0m     \u001b[38;5;28;01mraise\u001b[39;00m exception\n\u001b[0;32m    209\u001b[0m \u001b[38;5;28;01mfinally\u001b[39;00m:\n\u001b[0;32m    210\u001b[0m     \u001b[38;5;66;03m# credit to\u001b[39;00m\n\u001b[0;32m    211\u001b[0m     \u001b[38;5;66;03m# https://cosmicpercolator.com/2016/01/13/exception-leaks-in-python-2-and-3/\u001b[39;00m\n\u001b[0;32m    212\u001b[0m     \u001b[38;5;66;03m# as the __traceback__ object creates a cycle\u001b[39;00m\n\u001b[0;32m    213\u001b[0m     \u001b[38;5;28;01mdel\u001b[39;00m exception, replace_context, from_, with_traceback\n",
      "File \u001b[1;32m~\\anaconda3\\envs\\dev\\Lib\\site-packages\\sqlalchemy\\pool\\impl.py:143\u001b[0m, in \u001b[0;36mQueuePool._do_get\u001b[1;34m(self)\u001b[0m\n\u001b[0;32m    141\u001b[0m \u001b[38;5;28;01mif\u001b[39;00m \u001b[38;5;28mself\u001b[39m\u001b[38;5;241m.\u001b[39m_inc_overflow():\n\u001b[0;32m    142\u001b[0m     \u001b[38;5;28;01mtry\u001b[39;00m:\n\u001b[1;32m--> 143\u001b[0m         \u001b[38;5;28;01mreturn\u001b[39;00m \u001b[38;5;28mself\u001b[39m\u001b[38;5;241m.\u001b[39m_create_connection()\n\u001b[0;32m    144\u001b[0m     \u001b[38;5;28;01mexcept\u001b[39;00m:\n\u001b[0;32m    145\u001b[0m         \u001b[38;5;28;01mwith\u001b[39;00m util\u001b[38;5;241m.\u001b[39msafe_reraise():\n",
      "File \u001b[1;32m~\\anaconda3\\envs\\dev\\Lib\\site-packages\\sqlalchemy\\pool\\base.py:256\u001b[0m, in \u001b[0;36mPool._create_connection\u001b[1;34m(self)\u001b[0m\n\u001b[0;32m    253\u001b[0m \u001b[38;5;28;01mdef\u001b[39;00m \u001b[38;5;21m_create_connection\u001b[39m(\u001b[38;5;28mself\u001b[39m):\n\u001b[0;32m    254\u001b[0m \u001b[38;5;250m    \u001b[39m\u001b[38;5;124;03m\"\"\"Called by subclasses to create a new ConnectionRecord.\"\"\"\u001b[39;00m\n\u001b[1;32m--> 256\u001b[0m     \u001b[38;5;28;01mreturn\u001b[39;00m _ConnectionRecord(\u001b[38;5;28mself\u001b[39m)\n",
      "File \u001b[1;32m~\\anaconda3\\envs\\dev\\Lib\\site-packages\\sqlalchemy\\pool\\base.py:371\u001b[0m, in \u001b[0;36m_ConnectionRecord.__init__\u001b[1;34m(self, pool, connect)\u001b[0m\n\u001b[0;32m    369\u001b[0m \u001b[38;5;28mself\u001b[39m\u001b[38;5;241m.\u001b[39m__pool \u001b[38;5;241m=\u001b[39m pool\n\u001b[0;32m    370\u001b[0m \u001b[38;5;28;01mif\u001b[39;00m connect:\n\u001b[1;32m--> 371\u001b[0m     \u001b[38;5;28mself\u001b[39m\u001b[38;5;241m.\u001b[39m__connect()\n\u001b[0;32m    372\u001b[0m \u001b[38;5;28mself\u001b[39m\u001b[38;5;241m.\u001b[39mfinalize_callback \u001b[38;5;241m=\u001b[39m deque()\n",
      "File \u001b[1;32m~\\anaconda3\\envs\\dev\\Lib\\site-packages\\sqlalchemy\\pool\\base.py:665\u001b[0m, in \u001b[0;36m_ConnectionRecord.__connect\u001b[1;34m(self)\u001b[0m\n\u001b[0;32m    663\u001b[0m     \u001b[38;5;28mself\u001b[39m\u001b[38;5;241m.\u001b[39mfresh \u001b[38;5;241m=\u001b[39m \u001b[38;5;28;01mTrue\u001b[39;00m\n\u001b[0;32m    664\u001b[0m \u001b[38;5;28;01mexcept\u001b[39;00m \u001b[38;5;167;01mException\u001b[39;00m \u001b[38;5;28;01mas\u001b[39;00m e:\n\u001b[1;32m--> 665\u001b[0m     \u001b[38;5;28;01mwith\u001b[39;00m util\u001b[38;5;241m.\u001b[39msafe_reraise():\n\u001b[0;32m    666\u001b[0m         pool\u001b[38;5;241m.\u001b[39mlogger\u001b[38;5;241m.\u001b[39mdebug(\u001b[38;5;124m\"\u001b[39m\u001b[38;5;124mError on connect(): \u001b[39m\u001b[38;5;132;01m%s\u001b[39;00m\u001b[38;5;124m\"\u001b[39m, e)\n\u001b[0;32m    667\u001b[0m \u001b[38;5;28;01melse\u001b[39;00m:\n\u001b[0;32m    668\u001b[0m     \u001b[38;5;66;03m# in SQLAlchemy 1.4 the first_connect event is not used by\u001b[39;00m\n\u001b[0;32m    669\u001b[0m     \u001b[38;5;66;03m# the engine, so this will usually not be set\u001b[39;00m\n",
      "File \u001b[1;32m~\\anaconda3\\envs\\dev\\Lib\\site-packages\\sqlalchemy\\util\\langhelpers.py:70\u001b[0m, in \u001b[0;36msafe_reraise.__exit__\u001b[1;34m(self, type_, value, traceback)\u001b[0m\n\u001b[0;32m     68\u001b[0m     \u001b[38;5;28mself\u001b[39m\u001b[38;5;241m.\u001b[39m_exc_info \u001b[38;5;241m=\u001b[39m \u001b[38;5;28;01mNone\u001b[39;00m  \u001b[38;5;66;03m# remove potential circular references\u001b[39;00m\n\u001b[0;32m     69\u001b[0m     \u001b[38;5;28;01mif\u001b[39;00m \u001b[38;5;129;01mnot\u001b[39;00m \u001b[38;5;28mself\u001b[39m\u001b[38;5;241m.\u001b[39mwarn_only:\n\u001b[1;32m---> 70\u001b[0m         compat\u001b[38;5;241m.\u001b[39mraise_(\n\u001b[0;32m     71\u001b[0m             exc_value,\n\u001b[0;32m     72\u001b[0m             with_traceback\u001b[38;5;241m=\u001b[39mexc_tb,\n\u001b[0;32m     73\u001b[0m         )\n\u001b[0;32m     74\u001b[0m \u001b[38;5;28;01melse\u001b[39;00m:\n\u001b[0;32m     75\u001b[0m     \u001b[38;5;28;01mif\u001b[39;00m \u001b[38;5;129;01mnot\u001b[39;00m compat\u001b[38;5;241m.\u001b[39mpy3k \u001b[38;5;129;01mand\u001b[39;00m \u001b[38;5;28mself\u001b[39m\u001b[38;5;241m.\u001b[39m_exc_info \u001b[38;5;129;01mand\u001b[39;00m \u001b[38;5;28mself\u001b[39m\u001b[38;5;241m.\u001b[39m_exc_info[\u001b[38;5;241m1\u001b[39m]:\n\u001b[0;32m     76\u001b[0m         \u001b[38;5;66;03m# emulate Py3K's behavior of telling us when an exception\u001b[39;00m\n\u001b[0;32m     77\u001b[0m         \u001b[38;5;66;03m# occurs in an exception handler.\u001b[39;00m\n",
      "File \u001b[1;32m~\\anaconda3\\envs\\dev\\Lib\\site-packages\\sqlalchemy\\util\\compat.py:208\u001b[0m, in \u001b[0;36mraise_\u001b[1;34m(***failed resolving arguments***)\u001b[0m\n\u001b[0;32m    205\u001b[0m     exception\u001b[38;5;241m.\u001b[39m__cause__ \u001b[38;5;241m=\u001b[39m replace_context\n\u001b[0;32m    207\u001b[0m \u001b[38;5;28;01mtry\u001b[39;00m:\n\u001b[1;32m--> 208\u001b[0m     \u001b[38;5;28;01mraise\u001b[39;00m exception\n\u001b[0;32m    209\u001b[0m \u001b[38;5;28;01mfinally\u001b[39;00m:\n\u001b[0;32m    210\u001b[0m     \u001b[38;5;66;03m# credit to\u001b[39;00m\n\u001b[0;32m    211\u001b[0m     \u001b[38;5;66;03m# https://cosmicpercolator.com/2016/01/13/exception-leaks-in-python-2-and-3/\u001b[39;00m\n\u001b[0;32m    212\u001b[0m     \u001b[38;5;66;03m# as the __traceback__ object creates a cycle\u001b[39;00m\n\u001b[0;32m    213\u001b[0m     \u001b[38;5;28;01mdel\u001b[39;00m exception, replace_context, from_, with_traceback\n",
      "File \u001b[1;32m~\\anaconda3\\envs\\dev\\Lib\\site-packages\\sqlalchemy\\pool\\base.py:661\u001b[0m, in \u001b[0;36m_ConnectionRecord.__connect\u001b[1;34m(self)\u001b[0m\n\u001b[0;32m    659\u001b[0m \u001b[38;5;28;01mtry\u001b[39;00m:\n\u001b[0;32m    660\u001b[0m     \u001b[38;5;28mself\u001b[39m\u001b[38;5;241m.\u001b[39mstarttime \u001b[38;5;241m=\u001b[39m time\u001b[38;5;241m.\u001b[39mtime()\n\u001b[1;32m--> 661\u001b[0m     \u001b[38;5;28mself\u001b[39m\u001b[38;5;241m.\u001b[39mdbapi_connection \u001b[38;5;241m=\u001b[39m connection \u001b[38;5;241m=\u001b[39m pool\u001b[38;5;241m.\u001b[39m_invoke_creator(\u001b[38;5;28mself\u001b[39m)\n\u001b[0;32m    662\u001b[0m     pool\u001b[38;5;241m.\u001b[39mlogger\u001b[38;5;241m.\u001b[39mdebug(\u001b[38;5;124m\"\u001b[39m\u001b[38;5;124mCreated new connection \u001b[39m\u001b[38;5;132;01m%r\u001b[39;00m\u001b[38;5;124m\"\u001b[39m, connection)\n\u001b[0;32m    663\u001b[0m     \u001b[38;5;28mself\u001b[39m\u001b[38;5;241m.\u001b[39mfresh \u001b[38;5;241m=\u001b[39m \u001b[38;5;28;01mTrue\u001b[39;00m\n",
      "File \u001b[1;32m~\\anaconda3\\envs\\dev\\Lib\\site-packages\\sqlalchemy\\engine\\create.py:590\u001b[0m, in \u001b[0;36mcreate_engine.<locals>.connect\u001b[1;34m(connection_record)\u001b[0m\n\u001b[0;32m    588\u001b[0m         \u001b[38;5;28;01mif\u001b[39;00m connection \u001b[38;5;129;01mis\u001b[39;00m \u001b[38;5;129;01mnot\u001b[39;00m \u001b[38;5;28;01mNone\u001b[39;00m:\n\u001b[0;32m    589\u001b[0m             \u001b[38;5;28;01mreturn\u001b[39;00m connection\n\u001b[1;32m--> 590\u001b[0m \u001b[38;5;28;01mreturn\u001b[39;00m dialect\u001b[38;5;241m.\u001b[39mconnect(\u001b[38;5;241m*\u001b[39mcargs, \u001b[38;5;241m*\u001b[39m\u001b[38;5;241m*\u001b[39mcparams)\n",
      "File \u001b[1;32m~\\anaconda3\\envs\\dev\\Lib\\site-packages\\sqlalchemy\\engine\\default.py:597\u001b[0m, in \u001b[0;36mDefaultDialect.connect\u001b[1;34m(self, *cargs, **cparams)\u001b[0m\n\u001b[0;32m    595\u001b[0m \u001b[38;5;28;01mdef\u001b[39;00m \u001b[38;5;21mconnect\u001b[39m(\u001b[38;5;28mself\u001b[39m, \u001b[38;5;241m*\u001b[39mcargs, \u001b[38;5;241m*\u001b[39m\u001b[38;5;241m*\u001b[39mcparams):\n\u001b[0;32m    596\u001b[0m     \u001b[38;5;66;03m# inherits the docstring from interfaces.Dialect.connect\u001b[39;00m\n\u001b[1;32m--> 597\u001b[0m     \u001b[38;5;28;01mreturn\u001b[39;00m \u001b[38;5;28mself\u001b[39m\u001b[38;5;241m.\u001b[39mdbapi\u001b[38;5;241m.\u001b[39mconnect(\u001b[38;5;241m*\u001b[39mcargs, \u001b[38;5;241m*\u001b[39m\u001b[38;5;241m*\u001b[39mcparams)\n",
      "File \u001b[1;32m~\\anaconda3\\envs\\dev\\Lib\\site-packages\\psycopg2\\__init__.py:122\u001b[0m, in \u001b[0;36mconnect\u001b[1;34m(dsn, connection_factory, cursor_factory, **kwargs)\u001b[0m\n\u001b[0;32m    119\u001b[0m     kwasync[\u001b[38;5;124m'\u001b[39m\u001b[38;5;124masync_\u001b[39m\u001b[38;5;124m'\u001b[39m] \u001b[38;5;241m=\u001b[39m kwargs\u001b[38;5;241m.\u001b[39mpop(\u001b[38;5;124m'\u001b[39m\u001b[38;5;124masync_\u001b[39m\u001b[38;5;124m'\u001b[39m)\n\u001b[0;32m    121\u001b[0m dsn \u001b[38;5;241m=\u001b[39m _ext\u001b[38;5;241m.\u001b[39mmake_dsn(dsn, \u001b[38;5;241m*\u001b[39m\u001b[38;5;241m*\u001b[39mkwargs)\n\u001b[1;32m--> 122\u001b[0m conn \u001b[38;5;241m=\u001b[39m _connect(dsn, connection_factory\u001b[38;5;241m=\u001b[39mconnection_factory, \u001b[38;5;241m*\u001b[39m\u001b[38;5;241m*\u001b[39mkwasync)\n\u001b[0;32m    123\u001b[0m \u001b[38;5;28;01mif\u001b[39;00m cursor_factory \u001b[38;5;129;01mis\u001b[39;00m \u001b[38;5;129;01mnot\u001b[39;00m \u001b[38;5;28;01mNone\u001b[39;00m:\n\u001b[0;32m    124\u001b[0m     conn\u001b[38;5;241m.\u001b[39mcursor_factory \u001b[38;5;241m=\u001b[39m cursor_factory\n",
      "\u001b[1;31mOperationalError\u001b[0m: (psycopg2.OperationalError) connection to server at \"localhost\" (::1), port 5432 failed: FATAL:  password authentication failed for user \"username\"\n\n(Background on this error at: https://sqlalche.me/e/14/e3q8)"
     ]
    }
   ],
   "source": [
    "# Create the inspector and connect it to the engine\n",
    "inspector = inspect(engine)"
   ]
  },
  {
   "cell_type": "code",
   "execution_count": null,
   "id": "034cb940",
   "metadata": {},
   "outputs": [],
   "source": [
    "# Collect the names of tables within the database\n",
    "inspector.get_table_names()"
   ]
  },
  {
   "cell_type": "code",
   "execution_count": null,
   "id": "5152b55a",
   "metadata": {},
   "outputs": [],
   "source": [
    "# Using the inspector to print the column names within the 'dow' table and its types\n",
    "columns = inspector.get_columns('dow')\n",
    "for column in columns:\n",
    "    print(column[\"name\"], column[\"type\"])"
   ]
  }
 ],
 "metadata": {
  "kernelspec": {
   "display_name": "Python 3 (ipykernel)",
   "language": "python",
   "name": "python3"
  },
  "language_info": {
   "codemirror_mode": {
    "name": "ipython",
    "version": 3
   },
   "file_extension": ".py",
   "mimetype": "text/x-python",
   "name": "python",
   "nbconvert_exporter": "python",
   "pygments_lexer": "ipython3",
   "version": "3.11.5"
  }
 },
 "nbformat": 4,
 "nbformat_minor": 5
}
